<?xml version="1.0" ?>
<sdf version="1.5">
  <model name="create2">
    <link name="base">
      <inertial>
        <pose>0.001453 -0.000453 0.029787 0 0 0</pose>
        <inertia>
          <ixx>0.058640</ixx>
          <ixy>0.000124</ixy>
          <ixz>0.000615</ixz>
          <iyy>0.058786</iyy>
          <iyz>0.000014</iyz>
          <izz>1.532440</izz>
        </inertia>
        <mass>3.5</mass>
      </inertial>
      <collision name="base_collision">
        <pose>-0.0051 0 0.046 0 0 0</pose>
        <geometry>
          <cylinder>
            <radius>0.1625</radius>
	          <length>0.0719</length>
          </cylinder>
        </geometry>
      </collision>
      <visual name="base_visual">
        <pose>0 0 0.046 0 0 0</pose>
        <geometry>
          <mesh>
            <uri>model://create_crai/meshes/create2_visual.dae</uri>
          </mesh>
        </geometry>
      </visual>
      <collision name="front_wheel_collision">
        <pose>0.125 0 0.0105 0 0 0</pose>
        <geometry>
          <sphere>
            <radius>0.0105</radius>
          </sphere>
        </geometry>
        <surface>
          <friction>
            <ode>
              <mu>0.01</mu>
              <mu2>0.01</mu2>
              <fdir1>0 0 0</fdir1>
              <slip1>0</slip1>
              <slip2>0</slip2>
            </ode>
          </friction>
        </surface>
      </collision>
      <visual name="front_wheel_visual">
        <pose>0.125 0 0.0105 0 0 0</pose>
        <geometry>
          <sphere>
            <radius>0.0105</radius>
          </sphere>
        </geometry>
      </visual>
      <collision name="bumper_collision">
        <pose>0.0025 0 0.046 0 0 0</pose>
        <geometry>
          <cylinder>
            <radius>0.1615</radius>
	          <length>0.0719</length>
          </cylinder>
        </geometry>
      </collision>
      <sensor name="bumper_sensor" type="contact">
          <contact>
            <collision>bumper_collision</collision>
          </contact>
          <plugin name="bumper_plugin" filename="libgazebo_ros_bumper.so">
            <always_on>true</always_on>
            <update_rate>10.0</update_rate>
            <bumperTopicName>create2_bumper</bumperTopicName>
            <frameName>base</frameName>
          </plugin>
       </sensor>
    </link>
    <link name="top_plate">
      <pose>-0.0222 0 0.088 0 0 0</pose>
      <inertial>
        <inertia>
          <ixx>0.001000</ixx>
          <ixy>0.001000</ixy>
          <ixz>0.001000</ixz>
          <iyy>0.001000</iyy>
          <iyz>0.001000</iyz>
          <izz>0.001000</izz>
        </inertia>
        <mass>0.010000</mass>
      </inertial>
      <collision name="collision">
        <geometry>
          <box>
            <size>0.1524 0.254 0.00635</size>
          </box>
        </geometry>
      </collision>
      <visual name="visual">
        <geometry>
          <mesh>
            <uri>model://create_crai/meshes/green_top.dae</uri>
          </mesh>
        </geometry>
      </visual>
    </link>
    <link name="left_wheel">
      <pose>-0.0042 0.1175 0.036 0 0 0</pose>
      <inertial>
        <inertia>
          <ixx>0.001000</ixx>
          <ixy>0</ixy>
          <ixz>0</ixz>
          <iyy>0.001000</iyy>
          <iyz>0</iyz>
          <izz>0.001000</izz>
        </inertia>
        <mass>0.010000</mass>
      </inertial>
      <collision name="collision">
        <pose>0 0 0 0 1.570700 1.570700</pose>
        <geometry>
          <cylinder>
            <radius>0.036000</radius>
            <length>0.02000</length>
          </cylinder>
        </geometry>
        <surface>
          <friction>
            <ode>
              <mu>10</mu>
              <mu2>10</mu2>
              <fdir1>0 0 0</fdir1>
              <slip1>0</slip1>
              <slip2>0</slip2>
            </ode>
          </friction>
        </surface>
      </collision>
      <visual name="visual">
        <pose>0 0 0 0 1.570700 1.570700</pose>
        <geometry>
          <cylinder>
            <radius>0.036000</radius>
            <length>0.02000</length>
          </cylinder>
        </geometry>
      </visual>
    </link>
    <link name="right_wheel">
      <pose>-0.0042 -0.1175 0.036 0 0 0</pose>
      <inertial>
        <inertia>
          <ixx>0.001000</ixx>
          <ixy>0</ixy>
          <ixz>0</ixz>
          <iyy>0.001000</iyy>
          <iyz>0</iyz>
          <izz>0.001000</izz>
        </inertia>
        <mass>0.010000</mass>
      </inertial>
      <collision name="collision">
        <pose>0 0 0 0 1.570700 1.570700</pose>
        <geometry>
          <cylinder>
            <radius>0.036000</radius>
            <length>0.02000</length>
          </cylinder>
        </geometry>
        <surface>
          <friction>
            <ode>
              <mu>10</mu>
              <mu2>10</mu2>
              <fdir1>0 0 0</fdir1>
              <slip1>0</slip1>
              <slip2>0</slip2>
            </ode>
          </friction>
        </surface>
      </collision>
      <visual name="visual">
        <pose>0 0 0 0 1.570700 1.570700</pose>
        <geometry>
          <cylinder>
            <radius>0.036000</radius>
            <length>0.02000</length>
          </cylinder>
        </geometry>
      </visual>
    </link>
    <joint name="base2left_wheel" type="revolute">
      <parent>base</parent>
      <child>left_wheel</child>
      <axis>
        <xyz>0 1 0</xyz>
        <use_parent_model_frame>true</use_parent_model_frame>
      </axis>
    </joint>
    <joint name="base2right_wheel" type="revolute">
      <parent>base</parent>
      <child>right_wheel</child>
      <axis>
        <xyz>0 1 0</xyz>
        <use_parent_model_frame>true</use_parent_model_frame>
      </axis>
    </joint>
    <joint name="base2top_plate" type="revolute">
      <parent>base</parent>
      <child>top_plate</child>
      <axis>
      <xyz>0 0 1</xyz>
      <limit>
        <upper>0</upper>
        <lower>0</lower>
      </limit>
  </axis>
    </joint>

  <plugin name="differential_drive_controller" filename="libgazebo_ros_diff_drive.so">
    <alwaysOn>true</alwaysOn>
    <updateRate>10.0</updateRate>
    <leftJoint>base2left_wheel</leftJoint>
    <rightJoint>base2right_wheel</rightJoint>
    <wheelSeparation>0.235</wheelSeparation>
    <wheelDiameter>0.072</wheelDiameter>
    <wheeltorque>5</wheeltorque>
    <commandTopic>create2_cmd_vel</commandTopic>
    <odometryTopic>create2_odom</odometryTopic>
    <odometryFrame>base</odometryFrame>
    <robotBaseFrame>base</robotBaseFrame>
    
    <rosDebugLevel>na</rosDebugLevel>
    <publishWheelTF>false</publishWheelTF>
    <publishWheelJointState>false</publishWheelJointState>
    <wheelAcceleration>0</wheelAcceleration>
    
  </plugin>


  </model>
</sdf>
